Workbook
Name Orders: #REF!
Name People: #REF!
Name Returns: #REF!

Sheet Pivot_Region_Sales
A3: Row Labels | B3: Sum of Sales
A4: West | B4: 739813.61
A5: East | B5: 691828.17
A6: Central | B6: 503170.67
A7: South | B7: 391721.91
A8: Grand Total | B8: 2326534.4

Sheet Pivot_Category_Sales
A3: Row Labels | B3: Sum of Sales
A4: Technology | B4: 839893.28
A5: Furniture | B5: 754747.76
A6: Office Supplies | B6: 731893.31
A7: Grand Total | B7: 2326534.4

Sheet Pivot_ShipMode_Orders
A3: Row Labels | B3: Count of Order ID
A4: Standard Class | B4: 6120
A5: Second Class | B5: 1979
A6: First Class | B6: 1548
A7: Same Day | B7: 547
A8: Grand Total | B8: 10194

Sheet Pivot_Segment_Sales
A3: Row Labels | B3: Sum of Sales
A4: Consumer | B4: 1170659.8
A5: Corporate | B5: 715806.13
A6: Home Office | B6: 440068.43
A7: Grand Total | B7: 2326534.4

Sheet Pivot_Monthly_Sales
A3: Row Labels | B3: Sum of Sales
A4: ноя | B4: 352665.99
A5: дек | B5: 330218.18
A6: сен | B6: 308883.67
A7: мар | B7: 210672.09
A8: окт | B8: 207126.26
A9: авг | B9: 161821.91
A10: май | B10: 158765.03
A11: июн | B11: 153460
A12: июл | B12: 149001.71
A13: апр | B13: 138098.75
A14: янв | B14: 96069.516
A15: фев | B15: 59751.251
A16: Grand Total | B16: 2326534.4

Sheet Orders
A1: Row ID | B1: Order ID | C1: Order Date | D1: Ship Date | E1: Ship Mode | F1: Customer ID | G1: Customer Name | H1: Segment | I1: Country/Region | J1: City | K1: State/Province | L1: Fixed_Postal | M1: Region | N1: Product ID | O1: Category | P1: Sub-Category | Q1: Product Name | R1: Sales | S1: Quantity | T1: Discount | U1: Profit | W1: Regional Manager | Y1: Profit_Status | AB1: SUMIFS(west) | AC1: SUMIFS(central) | AD1: SUMIFS(south) | AE1: SUMIFS(east) | AF1: COUNTIFS(west) | AG1: COUNTIFS(central) | AH1: COUNTIFS(south) | AI1: COUNTIFS(east)
A2: 1 | B2: US-2023-103800 | C2: 44929 | D2: 44933 | E2: Standard Class | F2: DP-13000 | G2: Darren Powers | H2: Consumer | I2: United States | J2: Houston | K2: Texas | L2: 77095 | M2: Central | N2: OFF-PA-10000174 | O2: Office Supplies | P2: Paper | Q2: Message Book, Wirebound, Four 5 1/2" X 4" Forms/Pg., 200 Dupl. Sets/Book | R2: 16.448 | S2: 2 | T2: 0.2 | U2: 5.5512 | W2: =INDEX(People!A:A,MATCH(M2,People!B:B,0)) -> Roxanne Rodriguez | Y2: =IF(U2<0,"Zərər",IF(U2<100,"Aşağı Qazanc","Yüksək Qazanc")) -> Aşağı Qazanc | AB2: =SUMIFS(R:R,M:M,"West",O:O,"Furniture") -> 260679.73 | AC2: =SUMIFS(R:R, M:M, "Central", O:O, "Furniture") -> 164537.65 | AD2: =SUMIFS(R:R, M:M,"South", O:O, "Furniture") -> 117298.68 | AE2: =SUMIFS(R:R,M:M,"East",O:O,"Furniture") -> 212231.7 | AF2: =COUNTIFS(M:M,"West",U:U,"<0") -> 321 | AG2: =COUNTIFS(M:M,"Central",U:U,"<0") -> 747 | AH2: =COUNTIFS(M:M,"South",U:U,"<0") -> 259 | AI2: =COUNTIFS(M:M,"East",U:U,"<0") -> 574
A3: =A2+1 -> 2 | B3: US-2023-112326 | C3: 44930 | D3: 44934 | E3: Standard Class | F3: PO-19195 | G3: Phillina Ober | H3: Home Office | I3: United States | J3: Naperville | K3: Illinois | L3: 60540 | M3: Central | N3: OFF-BI-10004094 | O3: Office Supplies | P3: Binders | Q3: GBC Standard Plastic Binding Systems Combs | R3: 3.54 | S3: 2 | T3: 0.8 | U3: -5.487 | W3: =INDEX(People!A:A,MATCH(M3,People!B:B,0)) -> Roxanne Rodriguez | Y3: =IF(U3<0,"Zərər",IF(U3<100,"Aşağı Qazanc","Yüksək Qazanc")) -> Zərər
A4: =A3+1 -> 3 | B4: US-2023-112326 | C4: 44930 | D4: 44934 | E4: Standard Class | F4: PO-19195 | G4: Phillina Ober | H4: Home Office | I4: United States | J4: Naperville | K4: Illinois | L4: 60540 | M4: Central | N4: OFF-LA-10003223 | O4: Office Supplies | P4: Labels | Q4: Avery 508 | R4: 11.784 | S4: 3 | T4: 0.2 | U4: 4.2717 | W4: =INDEX(People!A:A,MATCH(M4,People!B:B,0)) -> Roxanne Rodriguez | Y4: =IF(U4<0,"Zərər",IF(U4<100,"Aşağı Qazanc","Yüksək Qazanc")) -> Aşağı Qazanc
A5: =A4+1 -> 4 | B5: US-2023-112326 | C5: 44930 | D5: 44934 | E5: Standard Class | F5: PO-19195 | G5: Phillina Ober | H5: Home Office | I5: United States | J5: Naperville | K5: Illinois | L5: 60540 | M5: Central | N5: OFF-ST-10002743 | O5: Office Supplies | P5: Storage | Q5: SAFCO Boltless Steel Shelving | R5: 272.736 | S5: 3 | T5: 0.2 | U5: -64.7748 | W5: =INDEX(People!A:A,MATCH(M5,People!B:B,0)) -> Roxanne Rodriguez | Y5: =IF(U5<0,"Zərər",IF(U5<100,"Aşağı Qazanc","Yüksək Qazanc")) -> Zərər
A6: =A5+1 -> 5 | B6: US-2023-141817 | C6: 44931 | D6: 44938 | E6: Standard Class | F6: MB-18085 | G6: Mick Brown | H6: Consumer | I6: United States | J6: Philadelphia | K6: Pennsylvania | L6: 19143 | M6: East | N6: OFF-AR-10003478 | O6: Office Supplies | P6: Art | Q6: Avery Hi-Liter EverBold Pen Style Fluorescent Highlighters, 4/Pack | R6: 19.536 | S6: 3 | T6: 0.2 | U6: 4.884 | W6: =INDEX(People!A:A,MATCH(M6,People!B:B,0)) -> Chuck Magee | Y6: =IF(U6<0,"Zərər",IF(U6<100,"Aşağı Qazanc","Yüksək Qazanc")) -> Aşağı Qazanc
A7: =A6+1 -> 6 | B7: US-2023-167199 | C7: 44932 | D7: 44936 | E7: Standard Class | F7: ME-17320 | G7: Maria Etezadi | H7: Home Office | I7: United States | J7: Henderson | K7: Kentucky | L7: 42420 | M7: South | N7: FUR-CH-10004063 | O7: Furniture | P7: Chairs | Q7: Global Deluxe High-Back Manager's Chair | R7: 2573.82 | S7: 9 | T7: 0 | U7: 746.4078 | W7: =INDEX(People!A:A,MATCH(M7,People!B:B,0)) -> Fred Suzuki | Y7: =IF(U7<0,"Zərər",IF(U7<100,"Aşağı Qazanc","Yüksək Qazanc")) -> Yüksək Qazanc
A8: =A7+1 -> 7 | B8: US-2023-167199 | C8: 44932 | D8: 44936 | E8: Standard Class | F8: ME-17320 | G8: Maria Etezadi | H8: Home Office | I8: United States | J8: Henderson | K8: Kentucky | L8: 42420 | M8: South | N8: OFF-AR-10001662 | O8: Office Supplies | P8: Art | Q8: Rogers Handheld Barrel Pencil Sharpener | R8: 5.48 | S8: 2 | T8: 0 | U8: 1.4796 | W8: =INDEX(People!A:A,MATCH(M8,People!B:B,0)) -> Fred Suzuki | Y8: =IF(U8<0,"Zərər",IF(U8<100,"Aşağı Qazanc","Yüksək Qazanc")) -> Aşağı Qazanc
A9: =A8+1 -> 8 | B9: US-2023-106054 | C9: 44932 | D9: 44933 | E9: First Class | F9: JO-15145 | G9: Jack O'Briant | H9: Corporate | I9: United States | J9: Athens | K9: Georgia | L9: 30605 | M9: South | N9: OFF-AR-10002399 | O9: Office Supplies | P9: Art | Q9: Dixon Prang Watercolor Pencils, 10-Color Set with Brush | R9: 12.78 | S9: 3 | T9: 0 | U9: 5.2398 | W9: =INDEX(People!A:A,MATCH(M9,People!B:B,0)) -> Fred Suzuki | Y9: =IF(U9<0,"Zərər",IF(U9<100,"Aşağı Qazanc","Yüksək Qazanc")) -> Aşağı Qazanc
A10: =A9+1 -> 9 | B10: US-2023-167199 | C10: 44932 | D10: 44936 | E10: Standard Class | F10: ME-17320 | G10: Maria Etezadi | H10: Home Office | I10: United States | J10: Henderson | K10: Kentucky | L10: 42420 | M10: South | N10: OFF-BI-10004632 | O10: Office Supplies | P10: Binders | Q10: Ibico Hi-Tech Manual Binding System | R10: 609.98 | S10: 2 | T10: 0 | U10: 274.491 | W10: =INDEX(People!A:A,MATCH(M10,People!B:B,0)) -> Fred Suzuki | Y10: =IF(U10<0,"Zərər",IF(U10<100,"Aşağı Qazanc","Yüksək Qazanc")) -> Yüksək Qazanc
A11: =A10+1 -> 10 | B11: US-2023-167199 | C11: 44932 | D11: 44936 | E11: Standard Class | F11: ME-17320 | G11: Maria Etezadi | H11: Home Office | I11: United States | J11: Henderson | K11: Kentucky | L11: 42420 | M11: South | N11: OFF-FA-10001883 | O11: Office Supplies | P11: Fasteners | Q11: Alliance Super-Size Bands, Assorted Sizes | R11: 31.12 | S11: 4 | T11: 0 | U11: 0.3112 | W11: =INDEX(People!A:A,MATCH(M11,People!B:B,0)) -> Fred Suzuki | Y11: =IF(U11<0,"Zərər",IF(U11<100,"Aşağı Qazanc","Yüksək Qazanc")) -> Aşağı Qazanc
A12: =A11+1 -> 11 | B12: US-2023-167199 | C12: 44932 | D12: 44936 | E12: Standard Class | F12: ME-17320 | G12: Maria Etezadi | H12: Home Office | I12: United States | J12: Henderson | K12: Kentucky | L12: 42420 | M12: South | N12: OFF-PA-10000955 | O12: Office Supplies | P12: Paper | Q12: Southworth 25% Cotton Granite Paper & Envelopes | R12: 6.54 | S12: 1 | T12: 0 | U12: 3.0084 | W12: =INDEX(People!A:A,MATCH(M12,People!B:B,0)) -> Fred Suzuki | Y12: =IF(U12<0,"Zərər",IF(U12<100,"Aşağı Qazanc","Yüksək Qazanc")) -> Aşağı Qazanc
A13: =A12+1 -> 12 | B13: US-2023-130813 | C13: 44932 | D13: 44934 | E13: Second Class | F13: LS-17230 | G13: Lycoris Saunders | H13: Consumer | I13: United States | J13: Los Angeles | K13: California | L13: 90049 | M13: West | N13: OFF-PA-10002005 | O13: Office Supplies | P13: Paper | Q13: Xerox 225 | R13: 19.44 | S13: 3 | T13: 0 | U13: 9.3312 | W13: =INDEX(People!A:A,MATCH(M13,People!B:B,0)) -> Sadie Pawthorne | Y13: =IF(U13<0,"Zərər",IF(U13<100,"Aşağı Qazanc","Yüksək Qazanc")) -> Aşağı Qazanc
A14: =A13+1 -> 13 | B14: US-2023-167199 | C14: 44932 | D14: 44936 | E14: Standard Class | F14: ME-17320 | G14: Maria Etezadi | H14: Home Office | I14: United States | J14: Henderson | K14: Kentucky | L14: 42420 | M14: South | N14: TEC-PH-10004539 | O14: Technology | P14: Phones | Q14: Wireless Extenders zBoost YX545 SOHO Signal Booster | R14: 755.96 | S14: 4 | T14: 0 | U14: 204.1092 | W14: =INDEX(People!A:A,MATCH(M14,People!B:B,0)) -> Fred Suzuki | Y14: =IF(U14<0,"Zərər",IF(U14<100,"Aşağı Qazanc","Yüksək Qazanc")) -> Yüksək Qazanc
... A62: =A61+1 -> 61 | B62: US-2023-110422 | C62: 44947 | D62: 44949 | E62: Second Class | F62: TB-21400 | G62: Tom Boeckenhauer | H62: Consumer | I62: United States | J62: Miami | K62: Florida | L62: 33180 | M62: South | N62: FUR-FU-10001889 | O62: Furniture | P62: Furnishings | Q62: Ultra Door Pull Handle | R62: 25.248 | S62: 3 | T62: 0.2 | U62: 4.1028 | W62: =INDEX(People!A:A,MATCH(M62,People!B:B,0)) -> Fred Suzuki | Y62: =IF(U62<0,"Zərər",IF(U62<100,"Aşağı Qazanc","Yüksək Qazanc")) -> Aşağı Qazanc
A63: =A62+1 -> 62 | B63: CA-2023-115238 | C63: 44947 | D63: 44950 | E63: Standard Class | F63: JW-15220 | G63: Jane Waco | H63: Corporate | I63: Canada | J63: Toronto | K63: Ontario | L63: M7A | M63: East | N63: FUR-FU-10001025 | O63: Furniture | P63: Furnishings | Q63: Eldon Imàge Series Desk Accessories, Clear | R63: 24.3 | S63: 5 | T63: 0 | U63: 10.45 | W63: =INDEX(People!A:A,MATCH(M63,People!B:B,0)) -> Chuck Magee | Y63: =IF(U63<0,"Zərər",IF(U63<100,"Aşağı Qazanc","Yüksək Qazanc")) -> Aşağı Qazanc
A64: =A63+1 -> 63 | B64: CA-2023-115238 | C64: 44947 | D64: 44950 | E64: Standard Class | F64: JW-15220 | G64: Jane Waco | H64: Corporate | I64: Canada | J64: Toronto | K64: Ontario | L64: M7A | M64: East | N64: FUR-FU-10002445 | O64: Furniture | P64: Furnishings | Q64: DAX Two-Tone Rosewood/Black Document Frame, Desktop, 5 x 7 | R64: 9.48 | S64: 1 | T64: 0 | U64: 3.79 | W64: =INDEX(People!A:A,MATCH(M64,People!B:B,0)) -> Chuck Magee | Y64: =IF(U64<0,"Zərər",IF(U64<100,"Aşağı Qazanc","Yüksək Qazanc")) -> Aşağı Qazanc
A65: =A64+1 -> 64 | B65: CA-2023-115238 | C65: 44947 | D65: 44950 | E65: Standard Class | F65: JW-15220 | G65: Jane Waco | H65: Corporate | I65: Canada | J65: Toronto | K65: Ontario | L65: M7A | M65: East | N65: FUR-FU-10002960 | O65: Furniture | P65: Furnishings | Q65: Eldon 200 Class Desk Accessories, Burgundy | R65: 31.4 | S65: 5 | T65: 0 | U65: 13.19 | W65: =INDEX(People!A:A,MATCH(M65,People!B:B,0)) -> Chuck Magee | Y65: =IF(U65<0,"Zərər",IF(U65<100,"Aşağı Qazanc","Yüksək Qazanc")) -> Aşağı Qazanc
A66: =A65+1 -> 65 | B66: CA-2023-115238 | C66: 44947 | D66: 44950 | E66: Standard Class | F66: JW-15220 | G66: Jane Waco | H66: Corporate | I66: Canada | J66: Toronto | K66: Ontario | L66: M7A | M66: East | N66: OFF-PA-10002689 | O66: Office Supplies | P66: Paper | Q66: Weyerhaeuser First Choice Laser/Copy Paper (20Lb. and 88 Bright) | R66: 6.48 | S66: 1 | T66: 0 | U66: 3.11 | W66: =INDEX(People!A:A,MATCH(M66,People!B:B,0)) -> Chuck Magee | Y66: =IF(U66<0,"Zərər",IF(U66<100,"Aşağı Qazanc","Yüksək Qazanc")) -> Aşağı Qazanc
A67: =A66+1 -> 66 | B67: CA-2023-115238 | C67: 44947 | D67: 44950 | E67: Standard Class | F67: JW-15220 | G67: Jane Waco | H67: Corporate | I67: Canada | J67: Toronto | K67: Ontario | L67: M7A | M67: East | N67: TEC-PH-10001300 | O67: Technology | P67: Phones | Q67: iKross Bluetooth Portable Keyboard + Cell Phone Stand Holder + Brush for Apple iPhone 5S 5C 5, 4S 4 | R67: 209.5 | S67: 10 | T67: 0 | U67: 58.66 | W67: =INDEX(People!A:A,MATCH(M67,People!B:B,0)) -> Chuck Magee | Y67: =IF(U67<0,"Zərər",IF(U67<100,"Aşağı Qazanc","Yüksək Qazanc")) -> Aşağı Qazanc
A68: =A67+1 -> 67 | B68: US-2023-146997 | C68: 44949 | D68: 44953 | E68: Standard Class | F68: SG-20605 | G68: Speros Goranitis | H68: Consumer | I68: United States | J68: Lafayette | K68: Indiana | L68: 47905 | M68: Central | N68: OFF-FA-10003467 | O68: Office Supplies | P68: Fasteners | Q68: Alliance Big Bands Rubber Bands, 12/Pack | R68: 5.94 | S68: 3 | T68: 0 | U68: 0 | W68: =INDEX(People!A:A,MATCH(M68,People!B:B,0)) -> Roxanne Rodriguez | Y68: =IF(U68<0,"Zərər",IF(U68<100,"Aşağı Qazanc","Yüksək Qazanc")) -> Aşağı Qazanc
A69: =A68+1 -> 68 | B69: US-2023-102645 | C69: 44949 | D69: 44954 | E69: Standard Class | F69: IM-15055 | G69: Ionia McGrath | H69: Consumer | I69: United States | J69: Las Vegas | K69: Nevada | L69: 89115 | M69: West | N69: OFF-PA-10001804 | O69: Office Supplies | P69: Paper | Q69: Xerox 195 | R69: 40.08 | S69: 6 | T69: 0 | U69: 19.2384 | W69: =INDEX(People!A:A,MATCH(M69,People!B:B,0)) -> Sadie Pawthorne | Y69: =IF(U69<0,"Zərər",IF(U69<100,"Aşağı Qazanc","Yüksək Qazanc")) -> Aşağı Qazanc
A70: =A69+1 -> 69 | B70: US-2023-167997 | C70: 44952 | D70: 44955 | E70: First Class | F70: CA-11965 | G70: Carol Adams | H70: Corporate | I70: United States | J70: Rapid City | K70: South Dakota | L70: 57701 | M70: Central | N70: FUR-BO-10004409 | O70: Furniture | P70: Bookcases | Q70: Safco Value Mate Series Steel Bookcases, Baked Enamel Finish on Steel, Gray | R70: 141.96 | S70: 2 | T70: 0 | U70: 39.7488 | W70: =INDEX(People!A:A,MATCH(M70,People!B:B,0)) -> Roxanne Rodriguez | Y70: =IF(U70<0,"Zərər",IF(U70<100,"Aşağı Qazanc","Yüksək Qazanc")) -> Aşağı Qazanc
A71: =A70+1 -> 70 | B71: US-2023-155502 | C71: 44952 | D71: 44957 | E71: Standard Class | F71: SD-20485 | G71: Shirley Daniels | H71: Home Office | I71: United States | J71: Alexandria | K71: Virginia | L71: 22304 | M71: South | N71: FUR-FU-10001847 | O71: Furniture | P71: Furnishings | Q71: Eldon Image Series Black Desk Accessories | R71: 12.42 | S71: 3 | T71: 0 | U71: 4.4712 | W71: =INDEX(People!A:A,MATCH(M71,People!B:B,0)) -> Fred Suzuki | Y71: =IF(U71<0,"Zərər",IF(U71<100,"Aşağı Qazanc","Yüksək Qazanc")) -> Aşağı Qazanc
A72: =A71+1 -> 71 | B72: US-2023-155502 | C72: 44952 | D72: 44957 | E72: Standard Class | F72: SD-20485 | G72: Shirley Daniels | H72: Home Office | I72: United States | J72: Alexandria | K72: Virginia | L72: 22304 | M72: South | N72: FUR-FU-10004587 | O72: Furniture | P72: Furnishings | Q72: GE General Use Halogen Bulbs, 100 Watts, 1 Bulb per Pack | R72: 62.82 | S72: 3 | T72: 0 | U72: 30.7818 | W72: =INDEX(People!A:A,MATCH(M72,People!B:B,0)) -> Fred Suzuki | Y72: =IF(U72<0,"Zərər",IF(U72<100,"Aşağı Qazanc","Yüksək Qazanc")) -> Aşağı Qazanc
A73: =A72+1 -> 72 | B73: US-2023-167997 | C73: 44952 | D73: 44955 | E73: First Class | F73: CA-11965 | G73: Carol Adams | H73: Corporate | I73: United States | J73: Rapid City | K73: South Dakota | L73: 57701 | M73: Central | N73: OFF-BI-10001758 | O73: Office Supplies | P73: Binders | Q73: Wilson Jones 14 Line Acrylic Coated Pressboard Data Binders | R73: 10.68 | S73: 2 | T73: 0 | U73: 5.0196 | W73: =INDEX(People!A:A,MATCH(M73,People!B:B,0)) -> Roxanne Rodriguez | Y73: =IF(U73<0,"Zərər",IF(U73<100,"Aşağı Qazanc","Yüksək Qazanc")) -> Aşağı Qazanc
A74: =A73+1 -> 73 | B74: US-2023-155502 | C74: 44952 | D74: 44957 | E74: Standard Class | F74: SD-20485 | G74: Shirley Daniels | H74: Home Office | I74: United States | J74: Alexandria | K74: Virginia | L74: 22304 | M74: South | N74: OFF-PA-10000380 | O74: Office Supplies | P74: Paper | Q74: REDIFORM Incoming/Outgoing Call Register, 11" X 8 1/2", 100 Messages | R74: 16.68 | S74: 2 | T74: 0 | U74: 8.34 | W74: =INDEX(People!A:A,MATCH(M74,People!B:B,0)) -> Fred Suzuki | Y74: =IF(U74<0,"Zərər",IF(U74<100,"Aşağı Qazanc","Yüksək Qazanc")) -> Aşağı Qazanc
A75: =A74+1 -> 74 | B75: US-2023-155502 | C75: 44952 | D75: 44957 | E75: Standard Class | F75: SD-20485 | G75: Shirley Daniels | H75: Home Office | I75: United States | J75: Alexandria | K75: Virginia | L75: 22304 | M75: South | N75: OFF-PA-10003072 | O75: Office Supplies | P75: Paper | Q75: Eureka Recycled Copy Paper 8 1/2" x 11", Ream | R75: 19.44 | S75: 3 | T75: 0 | U75: 9.3312 | W75: =INDEX(People!A:A,MATCH(M75,People!B:B,0)) -> Fred Suzuki | Y75: =IF(U75<0,"Zərər",IF(U75<100,"Aşağı Qazanc","Yüksək Qazanc")) -> Aşağı Qazanc
A76: =A75+1 -> 75 | B76: US-2023-155502 | C76: 44952 | D76: 44957 | E76: Standard Class | F76: SD-20485 | G76: Shirley Daniels | H76: Home Office | I76: United States | J76: Alexandria | K76: Virginia | L76: 22304 | M76: South | N76: OFF-ST-10004337 | O76: Office Supplies | P76: Storage | Q76: SAFCO Commercial Wire Shelving, 72h | R76: 489.92 | S76: 8 | T76: 0 | U76: 0 | W76: =INDEX(People!A:A,MATCH(M76,People!B:B,0)) -> Fred Suzuki | Y76: =IF(U76<0,"Zərər",IF(U76<100,"Aşağı Qazanc","Yüksək Qazanc")) -> Aşağı Qazanc
A77: =A76+1 -> 76 | B77: US-2023-155502 | C77: 44952 | D77: 44957 | E77: Standard Class | F77: SD-20485 | G77: Shirley Daniels | H77: Home Office | I77: United States | J77: Alexandria | K77: Virginia | L77: 22304 | M77: South | N77: TEC-PH-10002103 | O77: Technology | P77: Phones | Q77: Jabra SPEAK 410 | R77: 187.98 | S77: 2 | T77: 0 | U77: 52.6344 | W77: =INDEX(People!A:A,MATCH(M77,People!B:B,0)) -> Fred Suzuki | Y77: =IF(U77<0,"Zərər",IF(U77<100,"Aşağı Qazanc","Yüksək Qazanc")) -> Aşağı Qazanc
A78: =A77+1 -> 77 | B78: US-2023-155502 | C78: 44952 | D78: 44957 | E78: Standard Class | F78: SD-20485 | G78: Shirley Daniels | H78: Home Office | I78: United States | J78: Alexandria | K78: Virginia | L78: 22304 | M78: South | N78: TEC-PH-10004833 | O78: Technology | P78: Phones | Q78: Macally Suction Cup Mount | R78: 155.35 | S78: 13 | T78: 0 | U78: 0 | W78: =INDEX(People!A:A,MATCH(M78,People!B:B,0)) -> Fred Suzuki | Y78: =IF(U78<0,"Zərər",IF(U78<100,"Aşağı Qazanc","Yüksək Qazanc")) -> Aşağı Qazanc
A79: =A78+1 -> 78 | B79: US-2023-117163 | C79: 44953 | D79: 44959 | E79: Standard Class | F79: EJ-13720 | G79: Ed Jacobs | H79: Consumer | I79: United States | J79: San Diego | K79: California | L79: 92037 | M79: West | N79: FUR-TA-10003469 | O79: Furniture | P79: Tables | Q79: Balt Split Level Computer Training Table | R79: 333 | S79: 3 | T79: 0.2 | U79: -16.65 | W79: =INDEX(People!A:A,MATCH(M79,People!B:B,0)) -> Sadie Pawthorne | Y79: =IF(U79<0,"Zərər",IF(U79<100,"Aşağı Qazanc","Yüksək Qazanc")) -> Zərər
... A99: =A98+1 -> 98 | B99: US-2023-169390 | C99: 44964 | D99: 44967 | E99: Second Class | F99: CS-12250 | G99: Chris Selesnick | H99: Corporate | I99: United States | J99: New York City | K99: New York | L99: 10024 | M99: East | N99: OFF-ST-10001558 | O99: Office Supplies | P99: Storage | Q99: Acco Perma 4000 Stacking Storage Drawers | R99: 64.96 | S99: 4 | T99: 0 | U99: 9.744 | W99: =INDEX(People!A:A,MATCH(M99,People!B:B,0)) -> Chuck Magee | Y99: =IF(U99<0,"Zərər",IF(U99<100,"Aşağı Qazanc","Yüksək Qazanc")) -> Aşağı Qazanc
A100: =A99+1 -> 99 | B100: US-2023-107755 | C100: 44964 | D100: 44969 | E100: Standard Class | F100: CK-12760 | G100: Cyma Kinney | H100: Corporate | I100: United States | J100: Linden | K100: New Jersey | L100: 07036 | M100: East | N100: TEC-AC-10000710 | O100: Technology | P100: Accessories | Q100: Maxell DVD-RAM Discs | R100: 115.36 | S100: 7 | T100: 0 | U100: 49.6048 | W100: =INDEX(People!A:A,MATCH(M100,People!B:B,0)) -> Chuck Magee | Y100: =IF(U100<0,"Zərər",IF(U100<100,"Aşağı Qazanc","Yüksək Qazanc")) -> Aşağı Qazanc
A101: =A100+1 -> 100 | B101: US-2023-125759 | C101: 44965 | D101: 44966 | E101: First Class | F101: NM-18445 | G101: Nathan Mautz | H101: Home Office | I101: United States | J101: North Las Vegas | K101: Nevada | L101: 89031 | M101: West | N101: FUR-FU-10002111 | O101: Furniture | P101: Furnishings | Q101: Master Caster Door Stop, Large Brown | R101: 14.56 | S101: 2 | T101: 0 | U101: 5.5328 | W101: =INDEX(People!A:A,MATCH(M101,People!B:B,0)) -> Sadie Pawthorne | Y101: =IF(U101<0,"Zərər",IF(U101<100,"Aşağı Qazanc","Yüksək Qazanc")) -> Aşağı Qazanc
A102: =A101+1 -> 101 | B102: US-2023-168368 | C102: 44968 | D102: 44972 | E102: Second Class | F102: GA-14725 | G102: Guy Armstrong | H102: Consumer | I102: United States | J102: Columbia | K102: Missouri | L102: 65203 | M102: Central | N102: FUR-CH-10001146 | O102: Furniture | P102: Chairs | Q102: Global Value Mid-Back Manager's Chair, Gray | R102: 60.89 | S102: 1 | T102: 0 | U102: 15.2225 | W102: =INDEX(People!A:A,MATCH(M102,People!B:B,0)) -> Roxanne Rodriguez | Y102: =IF(U102<0,"Zərər",IF(U102<100,"Aşağı Qazanc","Yüksək Qazanc")) -> Aşağı Qazanc
A103: =A102+1 -> 102 | B103: US-2023-168368 | C103: 44968 | D103: 44972 | E103: Second Class | F103: GA-14725 | G103: Guy Armstrong | H103: Consumer | I103: United States | J103: Columbia | K103: Missouri | L103: 65203 | M103: Central | N103: FUR-FU-10002298 | O103: Furniture | P103: Furnishings | Q103: Rubbermaid ClusterMat Chairmats, Mat Size- 66" x 60", Lip 20" x 11" -90 Degree Angle | R103: 332.94 | S103: 3 | T103: 0 | U103: 53.2704 | W103: =INDEX(People!A:A,MATCH(M103,People!B:B,0)) -> Roxanne Rodriguez | Y103: =IF(U103<0,"Zərər",IF(U103<100,"Aşağı Qazanc","Yüksək Qazanc")) -> Aşağı Qazanc
A104: =A103+1 -> 103 | B104: US-2023-127614 | C104: 44968 | D104: 44972 | E104: Standard Class | F104: NF-18385 | G104: Natalie Fritzler | H104: Consumer | I104: United States | J104: Chesapeake | K104: Virginia | L104: 23320 | M104: South | N104: FUR-TA-10003715 | O104: Furniture | P104: Tables | Q104: Hon 2111 Invitation Series Corner Table | R104: 1256.22 | S104: 6 | T104: 0 | U104: 75.3732 | W104: =INDEX(People!A:A,MATCH(M104,People!B:B,0)) -> Fred Suzuki | Y104: =IF(U104<0,"Zərər",IF(U104<100,"Aşağı Qazanc","Yüksək Qazanc")) -> Aşağı Qazanc
A105: =A104+1 -> 104 | B105: US-2023-127614 | C105: 44968 | D105: 44972 | E105: Standard Class | F105: NF-18385 | G105: Natalie Fritzler | H105: Consumer | I105: United States | J105: Chesapeake | K105: Virginia | L105: 23320 | M105: South | N105: OFF-BI-10003291 | O105: Office Supplies | P105: Binders | Q105: Wilson Jones Leather-Like Binders with DublLock Round Rings | R105: 17.46 | S105: 2 | T105: 0 | U105: 8.2062 | W105: =INDEX(People!A:A,MATCH(M105,People!B:B,0)) -> Fred Suzuki | Y105: =IF(U105<0,"Zərər",IF(U105<100,"Aşağı Qazanc","Yüksək Qazanc")) -> Aşağı Qazanc
A106: =A105+1 -> 105 | B106: US-2023-168368 | C106: 44968 | D106: 44972 | E106: Second Class | F106: GA-14725 | G106: Guy Armstrong | H106: Consumer | I106: United States | J106: Columbia | K106: Missouri | L106: 65203 | M106: Central | N106: OFF-BI-10004654 | O106: Office Supplies | P106: Binders | Q106: VariCap6 Expandable Binder | R106: 51.9 | S106: 3 | T106: 0 | U106: 24.393 | W106: =INDEX(People!A:A,MATCH(M106,People!B:B,0)) -> Roxanne Rodriguez | Y106: =IF(U106<0,"Zərər",IF(U106<100,"Aşağı Qazanc","Yüksək Qazanc")) -> Aşağı Qazanc
...

Sheet People
A1: Regional Manager | B1: Region
A2: Sadie Pawthorne | B2: West
A3: Chuck Magee | B3: East
A4: Roxanne Rodriguez | B4: Central
A5: Fred Suzuki | B5: South

Sheet Products
A1: Product ID | B1: Product Name | C1: Supplier | D1: Unit Cost | E1: Target Margin
A2: OFF-PA-10000174 | B2: Message Book, Wirebound, Four 5 1/2" X 4" Forms/Pg., 200 Dupl. Sets/Book | C2: Staples | D2: 7.5 | E2: 25%
A3: OFF-BI-10004094 | B3: GBC Standard Plastic Binding Systems Combs | C3: Office Depot | D3: 15 | E3: 26%
A4: OFF-LA-10003223 | B4: Avery 508 | C4: HP | D4: 22.5 | E4: 27%
A5: OFF-ST-10002743 | B5: SAFCO Boltless Steel Shelving | C5: Canon | D5: 30 | E5: 28%
A6: OFF-AR-10003478 | B6: Avery Hi-Liter EverBold Pen Style Fluorescent Highlighters, 4/Pack | C6: Logitech | D6: 37.5 | E6: 29%
A7: FUR-CH-10004063 | B7: Global Deluxe High-Back Manager's Chair | C7: 3M | D7: 45 | E7: 30%
A8: OFF-AR-10001662 | B8: Rogers Handheld Barrel Pencil Sharpener | C8: Avery | D8: 52.5 | E8: 31%
A9: OFF-AR-10002399 | B9: Dixon Prang Watercolor Pencils, 10-Color Set with Brush | C9: IKEA | D9: 60 | E9: 32%
A10: OFF-BI-10004632 | B10: Ibico Hi-Tech Manual Binding System | C10: Samsung | D10: 67.5 | E10: 33%
A11: OFF-FA-10001883 | B11: Alliance Super-Size Bands, Assorted Sizes | C11: Dell | D11: 75 | E11: 34%
A12: OFF-PA-10000955 | B12: Southworth 25% Cotton Granite Paper & Envelopes | C12: Staples | D12: 82.5 | E12: 35%
A13: OFF-PA-10002005 | B13: Xerox 225 | C13: Office Depot | D13: 90 | E13: 36%
... A1863: FUR-BO-10002206 | B1863: Bush Saratoga Collection 5-Shelf Bookcase, Hanover Cherry, *Special Order | C1863: Office Depot | D1863: 15 | E1863: 30%

Sheet Returns
A1: Order ID | B1: Returned
A2: US-2023-100762 | B2: Yes
A3: US-2023-100867 | B3: Yes
A4: US-2023-102652 | B4: Yes
A5: US-2023-103373 | B5: Yes
A6: US-2023-103744 | B6: Yes
A7: US-2023-103940 | B7: Yes
A8: US-2023-104829 | B8: Yes
A9: US-2023-105270 | B9: Yes
A10: US-2023-108609 | B10: Yes
A11: US-2023-108861 | B11: Yes
A12: US-2023-109918 | B12: Yes
... A297: US-2026-155999 | B297: Yes
